../../data/hw6/bloom_filter_tests.ml failed on with:
Traceback (most recent call last):
  File "/home/dacosta/gitrepositories/instructor-repo/scripts/hw6.py", line 78, in processrepo
    ,_err=error):
  File "/home/dacosta/gitrepositories/instructor-repo/scripts/dependencies/sh/sh.py", line 394, in next
    self.wait()
  File "/home/dacosta/gitrepositories/instructor-repo/scripts/dependencies/sh/sh.py", line 334, in wait
    self._handle_exit_code(self.process.wait())
  File "/home/dacosta/gitrepositories/instructor-repo/scripts/dependencies/sh/sh.py", line 348, in _handle_exit_code
    self.process.stderr
sh.ErrorReturnCode_124: 

  RAN: '/usr/bin/timeout 180s bash -c utop -I ../../data/hw6/ ../../data/hw6/bloom_filter_tests.ml '

  STDOUT:
## is_empty(string hash)
0: []
1: []
2: []
3: []
4: []
5: [1]
6: []
7: [2]
8: [3]
9: [5; 3; 2; 4]
10: []
11: [4; 2; 2; 2; 4; 3]
12: []
13: [1; 1; 4; 6]
14: []
15: [5; 4; 4; 4]
16: [9; 7; 7; 10]
17: [9; 7; 4; 9; 2]
18: [6; 7; 6]
19: [4; 3; 5; 2; 1]
20: [9; 5; 2; 12; 10]
21: []
22: [3; 4; 2]
23: [1]
24: []
25: [2]
26: [12; 8; 4; 6; 3]
27: []
28: [6; 3]
29: [9; 8; 10; 15; 5; 20; 15; 12; 11; 17; 4; 18; 2; 10; 2; 2; 10; 17; 2; 4]
30: [24; 17]
31: [1]
32: [9; 23; 8; 4; 15; 13; 2; 2; 12; 12; 16; 8; 4; 21; 7]
33: [8]
34: [3; 4; 3; 8; 2; 4; 6; 5]
35: [4; 3; 6; 6; 2; 2]
36: [1]
37: []
38: [12; 1; 14; 3; 8; 2]
39: []
40: [2; 3; 10; 7; 10; 1; 8; 7; 8; 9]
41: [5; 17; 1; 10; 9; 6; 18; 9; 17; 15; 15; 7; 19; 18; 3; 10]
42: [1; 2; 30; 25; 3; 24; 1; 9; 30; 8... (6548 more, please see e.stdout)

  STDERR:

